Workbook

Sheet Inputs & Assumptions
B1: ABS CASH FLOW MODEL — INPUTS & ASSUMPTIONS
B2: Lender Finance Europe — Corporate Loan Securitisation. All calculations are live formulas; blue cells are inputs.
A4: 1. PORTFOLIO & LOAN TERMS
B5: Number of loans | C5: 30
B6: Original principal balance per loan (EUR) | C6: 20000000 | D6: each loan identical
B7: Original pool notional (EUR) | C7: =$C$5*$C$6 -> 600000000
B8: Interest period | C8: Quarterly
B9: Asset spread over 3M EURIBOR (bps) | C9: 500 | D9: E+500bps
B10: Asset margin (decimal) | C10: =$C$9/10000 -> 0.05
B11: Interest-only period (quarters) | C11: 4 | D11: no amort in q1-4
B12: Scheduled amortisation rate / quarter | C12: 0.03 | D12: 3% of opening bal, q5 onward
B13: Original loan tenor (quarters) | C13: 28 | D13: 7 years -> matches 7y CDR
B14: Origination window (months, 1 per month) | C14: 30 | D14: staggered maturities
B15: Day-count convention | C15: 30/360 (interest = rate/4)
A17: 2. DEFAULT, RECOVERY & PREPAYMENT (BASE CASE)
B18: Recovery rate on defaulted balance | C18: 0.6 | D18: base case
B19: Recovery lag (quarters) | C19: 8 | D19: 2 years after default
B20: Constant prepayment rate CPR (annual) | C20: 0.1 | D20: base case
A22: Cumulative default term structure (B-rated, from origination)
B23: Loan year | C23: 1 | D23: 2 | E23: 3 | F23: 4 | G23: 5 | H23: 6 | I23: 7
B24: Cumulative default rate | C24: 0.0318 | D24: 0.0746 | E24: 0.1126 | F24: 0.143 | G24: 0.1667 | H24: 0.1859 | I24: 0.201
B25: Marginal annual default (= diff) | C25: =C24 -> 0.0318 | D25: =D24-C24 -> 0.0428 | E25: =E24-D24 -> 0.038 | F25: =F24-E24 -> 0.0304 | G25: =G24-F24 -> 0.0237 | H25: =H24-G24 -> 0.0192 | I25: =I24-H24 -> 0.0151
B26: Marginal quarterly default (= annual / 4) | C26: =C25/4 -> 0.00795 | D26: =D25/4 -> 0.0107 | E26: =E25/4 -> 0.0095 | F26: =F25/4 -> 0.0076 | G26: =G25/4 -> 0.005925 | H26: =H25/4 -> 0.0048 | I26: =I25/4 -> 0.003775 | K26: Applied to outstanding balance; recoveries lagged 8q
A28: 3. LIABILITY STRUCTURE & WATERFALL
B29: Senior initial LTV | C29: 0.6 | D29: attachment
B30: Junior initial LTV | C30: 0.4
B31: Max senior LTV (= senior initial +5%) | C31: =$C$29+0.05 -> 0.65 | D31: de-levering trigger
B32: Senior spread over 3M EURIBOR (bps) | C32: 200 | D32: E+200bps
B33: Senior margin (decimal) | C33: =$C$32/10000 -> 0.02
B34: Senior legal tenor (quarters) | C34: 20 | D34: 5 years
B35: Senior costs & expenses (EUR / annum) | C35: 150000
B36: Senior costs / quarter (EUR) | C36: =$C$35/4 -> 37500
B37: Senior share of principal if >=20 loans | C37: 0.7
B38: Senior share of principal if 10-19 loans | C38: 0.8
B39: Senior share of principal if <10 loans | C39: 1
A41: 4. 3-MONTH EURIBOR — SPOT & FORWARD PATH
B42: EURIBOR spot (3M, current fixing) | C42: 0.02324 | D42: Src: euribor-rates.info ~07-Jul-2026; ECB depo 2.25% eff 17-Jun-26
B43: EURIBOR mode (1 = flat at spot, 2 = forward path) | C43: 1 | D43: switch to 2 to use the editable forward vector below
B44: Note: assets (E+500) & senior (E+200) both float, so the EURIBOR level largely nets out of credit metrics.
A46: Quarterly rate vectors (columns = projection quarters)
...

Sheet Asset Cash Flows
A1: PART 1 — ASSET CASH FLOW MODELLING
A2: Portfolio of 30 corporate loans (EUR 20m each), 3M EURIBOR + 500bps, quarterly. Values in EUR millions unless noted.
A4: STEP 2-3 CONTRACTUAL (EXPECTED) CASH FLOWS — per loan, before defaults/prepayments
A5: Loan-level projection (EUR m). Header = projection quarter. | E5: 1 | F5: 2 | G5: 3 | H5: 4 | I5: 5 | J5: 6 | K5: 7 | L5: 8 | M5: 9 | N5: 10 | O5: 11 | P5: 12 | Q5: 13 | R5: 14 | S5: 15 | T5: 16 | U5: 17 | V5: 18 | W5: 19 | X5: 20 | Y5: 21 | Z5: 22 | AA5: 23 | AB5: 24 | AC5: 25 | AD5: 26 | AE5: 27 | AF5: 28 | AG5: 29 | AH5: 30 | AI5: 31 | AJ5: 32 | AK5: 33 | AL5: 34 | AM5: 35 | AN5: 36
A6: Contractual principal due | B6: ='Inputs & Assumptions'!$B$102 -> 1 | E6: =IF(('Inputs & Assumptions'!$D$102+1)<='Inputs & Assumptions'!$C$13,INDEX('Inputs & Assumptions'!$D$70:$D$98,'Inputs & Assumptions'!$D$102+1+1),0) -> 0 | F6: =IF(('Inputs & Assumptions'!$D$102+2)<='Inputs & Assumptions'!$C$13,INDEX('Inputs & Assumptions'!$D$70:$D$98,'Inputs & Assumptions'!$D$102+2+1),0) -> 0 | G6: =IF(('Inputs & Assumptions'!$D$102+3)<='Inputs & Assumptions'!$C$13,INDEX('Inputs & Assumptions'!$D$70:$D$98,'Inputs & Assumptions'!$D$102+3+1),0) -> 0 | H6: =IF(('Inputs & Assumptions'!$D$102+4)<='Inputs & Assumptions'!$C$13,INDEX('Inputs & Assumptions'!$D$70:$D$98,'Inputs & Assumptions'!$D$102+4+1),0) -> 0 | I6: =IF(('Inputs & Assumptions'!$D$102+5)<='Inputs & Assumptions'!$C$13,INDEX('Inputs & Assumptions'!$D$70:$D$98,'Inputs & Assumptions'!$D$102+5+1),0) -> 600000 | J6: =IF(('Inputs & Assumptions'!$D$102+6)<='Inputs & Assumptions'!$C$13,INDEX('Inputs & Assumptions'!$D$70:$D$98,'Inputs & Assumptions'!$D$102+6+1),0) -> 582000 | K6: =IF(('Inputs & Assumptions'!$D$102+7)<='Inputs & Assumptions'!$C$13,INDEX('Inputs & Assumptions'!$D$70:$D$98,'Inputs & Assumptions'!$D$102+7+1),0) -> 564540 | L6: =IF(('Inputs & Assumptions'!$D$102+8)<='Inputs & Assumptions'!$C$13,INDEX('Inputs & Assumptions'!$D$70:$D$98,'Inputs & Assumptions'!$D$102+8+1),0) -> 547603.8 | M6: =IF(('Inputs & Assumptions'!$D$102+9)<='Inputs & Assumptions'!$C$13,INDEX('Inputs & Assumptions'!$D$70:$D$98,'Inputs & Assumptions'!$D$102+9+1),0) -> 531175.69 | N6: =IF(('Inputs & Assumptions'!$D$102+10)<='Inputs & Assumptions'!$C$13,INDEX('Inputs & Assumptions'!$D$70:$D$98,'Inputs & Assumptions'!$D$102+10+1),0) -> 515240.42 | O6: =IF(('Inputs & Assumptions'!$D$102+11)<='Inputs & Assumptions'!$C$13,INDEX('Inputs & Assumptions'!$D$70:$D$98,'Inputs & Assumptions'!$D$102+11+1),0) -> 499783.2 | P6: =IF(('Inputs & Assumptions'!$D$102+12)<='Inputs & Assumptions'!$C$13,INDEX('Inputs & Assumptions'!$D$70:$D$98,'Inputs & Assumptions'!$D$102+12+1),0) -> 484789.71 | Q6: =IF(('Inputs & Assumptions'!$D$102+13)<='Inputs & Assumptions'!$C$13,INDEX('Inputs & Assumptions'!$D$70:$D$98,'Inputs & Assumptions'!$D$102+13+1),0) -> 470246.02 | R6: =IF(('Inputs & Assumptions'!$D$102+14)<='Inputs & Assumptions'!$C$13,INDEX('Inputs & Assumptions'!$D$70:$D$98,'Inputs & Assumptions'!$D$102+14+1),0) -> 456138.64 | S6: =IF(('Inputs & Assumptions'!$D$102+15)<='Inputs & Assumptions'!$C$13,INDEX('Inputs & Assumptions'!$D$70:$D$98,'Inputs & Assumptions'!$D$102+15+1),0) -> 442454.48 | T6: =IF(('Inputs & Assumptions'!$D$102+16)<='Inputs & Assumptions'!$C$13,INDEX('Inputs & Assumptions'!$D$70:$D$98,'Inputs & Assumptions'!$D$102+16+1),0) -> 429180.84 | U6: =IF(('Inputs & Assumptions'!$D$102+17)<='Inputs & Assumptions'!$C$13,INDEX('Inputs & Assumptions'!$D$70:$D$98,'Inputs & Assumptions'!$D$102+17+1),0) -> 416305.42 | V6: =IF(('Inputs & Assumptions'!$D$102+18)<='Inputs & Assumptions'!$C$13,INDEX('Inputs & Assumptions'!$D$70:$D$98,'Inputs & Assumptions'!$D$102+18+1),0) -> 403816.25 | W6: =IF(('Inputs & Assumptions'!$D$102+19)<='Inputs & Assumptions'!$C$13,INDEX('Inputs & Assumptions'!$D$70:$D$98,'Inputs & Assumptions'!$D$102+19+1),0) -> 391701.77 | X6: =IF(('Inputs & Assumptions'!$D$102+20)<='Inputs & Assumptions'!$C$13,INDEX('Inputs & Assumptions'!$D$70:$D$98,'Inputs & Assumptions'!$D$102+20+1),0) -> 379950.71 | Y6: =IF(('Inputs & Assumptions'!$D$102+21)<='Inputs & Assumptions'!$C$13,INDEX('Inputs & Assumptions'!$D$70:$D$98,'Inputs & Assumptions'!$D$102+21+1),0) -> 368552.19 | Z6: =IF(('Inputs & Assumptions'!$D$102+22)<='Inputs & Assumptions'!$C$13,INDEX('Inputs & Assumptions'!$D$70:$D$98,'Inputs & Assumptions'!$D$102+22+1),0) -> 357495.63 | AA6: =IF(('Inputs & Assumptions'!$D$102+23)<='Inputs & Assumptions'!$C$13,INDEX('Inputs & Assumptions'!$D$70:$D$98,'Inputs & Assumptions'!$D$102+23+1),0) -> 346770.76 | AB6: =IF(('Inputs & Assumptions'!$D$102+24)<='Inputs & Assumptions'!$C$13,INDEX('Inputs & Assumptions'!$D$70:$D$98,'Inputs & Assumptions'!$D$102+24+1),0) -> 336367.63 | AC6: =IF(('Inputs & Assumptions'!$D$102+25)<='Inputs & Assumptions'!$C$13,INDEX('Inputs & Assumptions'!$D$70:$D$98,'Inputs & Assumptions'!$D$102+25+1),0) -> 326276.61 | AD6: =IF(('Inputs & Assumptions'!$D$102+26)<='Inputs & Assumptions'!$C$13,INDEX('Inputs & Assumptions'!$D$70:$D$98,'Inputs & Assumptions'!$D$102+26+1),0) -> 316488.31 | AE6: =IF(('Inputs & Assumptions'!$D$102+27)<='Inputs & Assumptions'!$C$13,INDEX('Inputs & Assumptions'!$D$70:$D$98,'Inputs & Assumptions'!$D$102+27+1),0) -> 306993.66 | AF6: =IF(('Inputs & Assumptions'!$D$102+28)<='Inputs & Assumptions'!$C$13,INDEX('Inputs & Assumptions'!$D$70:$D$98,'Inputs & Assumptions'!$D$102+28+1),0) -> 9926128.3 | AG6: =IF(('Inputs & Assumptions'!$D$102+29)<='Inputs & Assumptions'!$C$13,INDEX('Inputs & Assumptions'!$D$70:$D$98,'Inputs & Assumptions'!$D$102+29+1),0) -> 0 | AH6: =IF(('Inputs & Assumptions'!$D$102+30)<='Inputs & Assumptions'!$C$13,INDEX('Inputs & Assumptions'!$D$70:$D$98,'Inputs & Assumptions'!$D$102+30+1),0) -> 0 | AI6: =IF(('Inputs & Assumptions'!$D$102+31)<='Inputs & Assumptions'!$C$13,INDEX('Inputs & Assumptions'!$D$70:$D$98,'Inputs & Assumptions'!$D$102+31+1),0) -> 0 | AJ6: =IF(('Inputs & Assumptions'!$D$102+32)<='Inputs & Assumptions'!$C$13,INDEX('Inputs & Assumptions'!$D$70:$D$98,'Inputs & Assumptions'!$D$102+32+1),0) -> 0 | AK6: =IF(('Inputs & Assumptions'!$D$102+33)<='Inputs & Assumptions'!$C$13,INDEX('Inputs & Assumptions'!$D$70:$D$98,'Inputs & Assumptions'!$D$102+33+1),0) -> 0 | AL6: =IF(('Inputs & Assumptions'!$D$102+34)<='Inputs & Assumptions'!$C$13,INDEX('Inputs & Assumptions'!$D$70:$D$98,'Inputs & Assumptions'!$D$102+34+1),0) -> 0 | AM6: =IF(('Inputs & Assumptions'!$D$102+35)<='Inputs & Assumptions'!$C$13,INDEX('Inputs & Assumptions'!$D$70:$D$98,'Inputs & Assumptions'!$D$102+35+1),0) -> 0 | AN6: =IF(('Inputs & Assumptions'!$D$102+36)<='Inputs & Assumptions'!$C$13,INDEX('Inputs & Assumptions'!$D$70:$D$98,'Inputs & Assumptions'!$D$102+36+1),0) -> 0
B7: ='Inputs & Assumptions'!$B$103 -> 2 | E7: =IF(('Inputs & Assumptions'!$D$103+1)<='Inputs & Assumptions'!$C$13,INDEX('Inputs & Assumptions'!$D$70:$D$98,'Inputs & Assumptions'!$D$103+1+1),0) -> 0 | F7: =IF(('Inputs & Assumptions'!$D$103+2)<='Inputs & Assumptions'!$C$13,INDEX('Inputs & Assumptions'!$D$70:$D$98,'Inputs & Assumptions'!$D$103+2+1),0) -> 0 | G7: =IF(('Inputs & Assumptions'!$D$103+3)<='Inputs & Assumptions'!$C$13,INDEX('Inputs & Assumptions'!$D$70:$D$98,'Inputs & Assumptions'!$D$103+3+1),0) -> 0 | H7: =IF(('Inputs & Assumptions'!$D$103+4)<='Inputs & Assumptions'!$C$13,INDEX('Inputs & Assumptions'!$D$70:$D$98,'Inputs & Assumptions'!$D$103+4+1),0) -> 600000 | I7: =IF(('Inputs & Assumptions'!$D$103+5)<='Inputs & Assumptions'!$C$13,INDEX('Inputs & Assumptions'!$D$70:$D$98,'Inputs & Assumptions'!$D$103+5+1),0) -> 582000 | J7: =IF(('Inputs & Assumptions'!$D$103+6)<='Inputs & Assumptions'!$C$13,INDEX('Inputs & Assumptions'!$D$70:$D$98,'Inputs & Assumptions'!$D$103+6+1),0) -> 564540 | K7: =IF(('Inputs & Assumptions'!$D$103+7)<='Inputs & Assumptions'!$C$13,INDEX('Inputs & Assumptions'!$D$70:$D$98,'Inputs & Assumptions'!$D$103+7+1),0) -> 547603.8 | L7: =IF(('Inputs & Assumptions'!$D$103+8)<='Inputs & Assumptions'!$C$13,INDEX('Inputs & Assumptions'!$D$70:$D$98,'Inputs & Assumptions'!$D$103+8+1),0) -> 531175.69 | M7: =IF(('Inputs & Assumptions'!$D$103+9)<='Inputs & Assumptions'!$C$13,INDEX('Inputs & Assumptions'!$D$70:$D$98,'Inputs & Assumptions'!$D$103+9+1),0) -> 515240.42 | N7: =IF(('Inputs & Assumptions'!$D$103+10)<='Inputs & Assumptions'!$C$13,INDEX('Inputs & Assumptions'!$D$70:$D$98,'Inputs & Assumptions'!$D$103+10+1),0) -> 499783.2 | O7: =IF(('Inputs & Assumptions'!$D$103+11)<='Inputs & Assumptions'!$C$13,INDEX('Inputs & Assumptions'!$D$70:$D$98,'Inputs & Assumptions'!$D$103+11+1),0) -> 484789.71 | P7: =IF(('Inputs & Assumptions'!$D$103+12)<='Inputs & Assumptions'!$C$13,INDEX('Inputs & Assumptions'!$D$70:$D$98,'Inputs & Assumptions'!$D$103+12+1),0) -> 470246.02 | Q7: =IF(('Inputs & Assumptions'!$D$103+13)<='Inputs & Assumptions'!$C$13,INDEX('Inputs & Assumptions'!$D$70:$D$98,'Inputs & Assumptions'!$D$103+13+1),0) -> 456138.64 | R7: =IF(('Inputs & Assumptions'!$D$103+14)<='Inputs & Assumptions'!$C$13,INDEX('Inputs & Assumptions'!$D$70:$D$98,'Inputs & Assumptions'!$D$103+14+1),0) -> 442454.48 | S7: =IF(('Inputs & Assumptions'!$D$103+15)<='Inputs & Assumptions'!$C$13,INDEX('Inputs & Assumptions'!$D$70:$D$98,'Inputs & Assumptions'!$D$103+15+1),0) -> 429180.84 | T7: =IF(('Inputs & Assumptions'!$D$103+16)<='Inputs & Assumptions'!$C$13,INDEX('Inputs & Assumptions'!$D$70:$D$98,'Inputs & Assumptions'!$D$103+16+1),0) -> 416305.42 | U7: =IF(('Inputs & Assumptions'!$D$103+17)<='Inputs & Assumptions'!$C$13,INDEX('Inputs & Assumptions'!$D$70:$D$98,'Inputs & Assumptions'!$D$103+17+1),0) -> 403816.25 | V7: =IF(('Inputs & Assumptions'!$D$103+18)<='Inputs & Assumptions'!$C$13,INDEX('Inputs & Assumptions'!$D$70:$D$98,'Inputs & Assumptions'!$D$103+18+1),0) -> 391701.77 | W7: =IF(('Inputs & Assumptions'!$D$103+19)<='Inputs & Assumptions'!$C$13,INDEX('Inputs & Assumptions'!$D$70:$D$98,'Inputs & Assumptions'!$D$103+19+1),0) -> 379950.71 | X7: =IF(('Inputs & Assumptions'!$D$103+20)<='Inputs & Assumptions'!$C$13,INDEX('Inputs & Assumptions'!$D$70:$D$98,'Inputs & Assumptions'!$D$103+20+1),0) -> 368552.19 | Y7: =IF(('Inputs & Assumptions'!$D$103+21)<='Inputs & Assumptions'!$C$13,INDEX('Inputs & Assumptions'!$D$70:$D$98,'Inputs & Assumptions'!$D$103+21+1),0) -> 357495.63 | Z7: =IF(('Inputs & Assumptions'!$D$103+22)<='Inputs & Assumptions'!$C$13,INDEX('Inputs & Assumptions'!$D$70:$D$98,'Inputs & Assumptions'!$D$103+22+1),0) -> 346770.76 | AA7: =IF(('Inputs & Assumptions'!$D$103+23)<='Inputs & Assumptions'!$C$13,INDEX('Inputs & Assumptions'!$D$70:$D$98,'Inputs & Assumptions'!$D$103+23+1),0) -> 336367.63 | AB7: =IF(('Inputs & Assumptions'!$D$103+24)<='Inputs & Assumptions'!$C$13,INDEX('Inputs & Assumptions'!$D$70:$D$98,'Inputs & Assumptions'!$D$103+24+1),0) -> 326276.61 | AC7: =IF(('Inputs & Assumptions'!$D$103+25)<='Inputs & Assumptions'!$C$13,INDEX('Inputs & Assumptions'!$D$70:$D$98,'Inputs & Assumptions'!$D$103+25+1),0) -> 316488.31 | AD7: =IF(('Inputs & Assumptions'!$D$103+26)<='Inputs & Assumptions'!$C$13,INDEX('Inputs & Assumptions'!$D$70:$D$98,'Inputs & Assumptions'!$D$103+26+1),0) -> 306993.66 | AE7: =IF(('Inputs & Assumptions'!$D$103+27)<='Inputs & Assumptions'!$C$13,INDEX('Inputs & Assumptions'!$D$70:$D$98,'Inputs & Assumptions'!$D$103+27+1),0) -> 9926128.3 | AF7: =IF(('Inputs & Assumptions'!$D$103+28)<='Inputs & Assumptions'!$C$13,INDEX('Inputs & Assumptions'!$D$70:$D$98,'Inputs & Assumptions'!$D$103+28+1),0) -> 0 | AG7: =IF(('Inputs & Assumptions'!$D$103+29)<='Inputs & Assumptions'!$C$13,INDEX('Inputs & Assumptions'!$D$70:$D$98,'Inputs & Assumptions'!$D$103+29+1),0) -> 0 | AH7: =IF(('Inputs & Assumptions'!$D$103+30)<='Inputs & Assumptions'!$C$13,INDEX('Inputs & Assumptions'!$D$70:$D$98,'Inputs & Assumptions'!$D$103+30+1),0) -> 0 | AI7: =IF(('Inputs & Assumptions'!$D$103+31)<='Inputs & Assumptions'!$C$13,INDEX('Inputs & Assumptions'!$D$70:$D$98,'Inputs & Assumptions'!$D$103+31+1),0) -> 0 | AJ7: =IF(('Inputs & Assumptions'!$D$103+32)<='Inputs & Assumptions'!$C$13,INDEX('Inputs & Assumptions'!$D$70:$D$98,'Inputs & Assumptions'!$D$103+32+1),0) -> 0 | AK7: =IF(('Inputs & Assumptions'!$D$103+33)<='Inputs & Assumptions'!$C$13,INDEX('Inputs & Assumptions'!$D$70:$D$98,'Inputs & Assumptions'!$D$103+33+1),0) -> 0 | AL7: =IF(('Inputs & Assumptions'!$D$103+34)<='Inputs & Assumptions'!$C$13,INDEX('Inputs & Assumptions'!$D$70:$D$98,'Inputs & Assumptions'!$D$103+34+1),0) -> 0 | AM7: =IF(('Inputs & Assumptions'!$D$103+35)<='Inputs & Assumptions'!$C$13,INDEX('Inputs & Assumptions'!$D$70:$D$98,'Inputs & Assumptions'!$D$103+35+1),0) -> 0 | AN7: =IF(('Inputs & Assumptions'!$D$103+36)<='Inputs & Assumptions'!$C$13,INDEX('Inputs & Assumptions'!$D$70:$D$98,'Inputs & Assumptions'!$D$103+36+1),0) -> 0
B8: ='Inputs & Assumptions'!$B$104 -> 3 | E8: =IF(('Inputs & Assumptions'!$D$104+1)<='Inputs & Assumptions'!$C$13,INDEX('Inputs & Assumptions'!$D$70:$D$98,'Inputs & Assumptions'!$D$104+1+1),0) -> 0 | F8: =IF(('Inputs & Assumptions'!$D$104+2)<='Inputs & Assumptions'!$C$13,INDEX('Inputs & Assumptions'!$D$70:$D$98,'Inputs & Assumptions'!$D$104+2+1),0) -> 0 | G8: =IF(('Inputs & Assumptions'!$D$104+3)<='Inputs & Assumptions'!$C$13,INDEX('Inputs & Assumptions'!$D$70:$D$98,'Inputs & Assumptions'!$D$104+3+1),0) -> 0 | H8: =IF(('Inputs & Assumptions'!$D$104+4)<='Inputs & Assumptions'!$C$13,INDEX('Inputs & Assumptions'!$D$70:$D$98,'Inputs & Assumptions'!$D$104+4+1),0) -> 600000 | I8: =IF(('Inputs & Assumptions'!$D$104+5)<='Inputs & Assumptions'!$C$13,INDEX('Inputs & Assumptions'!$D$70:$D$98,'Inputs & Assumptions'!$D$104+5+1),0) -> 582000 | J8: =IF(('Inputs & Assumptions'!$D$104+6)<='Inputs & Assumptions'!$C$13,INDEX('Inputs & Assumptions'!$D$70:$D$98,'Inputs & Assumptions'!$D$104+6+1),0) -> 564540 | K8: =IF(('Inputs & Assumptions'!$D$104+7)<='Inputs & Assumptions'!$C$13,INDEX('Inputs & Assumptions'!$D$70:$D$98,'Inputs & Assumptions'!$D$104+7+1),0) -> 547603.8 | L8: =IF(('Inputs & Assumptions'!$D$104+8)<='Inputs & Assumptions'!$C$13,INDEX('Inputs & Assumptions'!$D$70:$D$98,'Inputs & Assumptions'!$D$104+8+1),0) -> 531175.69 | M8: =IF(('Inputs & Assumptions'!$D$104+9)<='Inputs & Assumptions'!$C$13,INDEX('Inputs & Assumptions'!$D$70:$D$98,'Inputs & Assumptions'!$D$104+9+1),0) -> 515240.42 | N8: =IF(('Inputs & Assumptions'!$D$104+10)<='Inputs & Assumptions'!$C$13,INDEX('Inputs & Assumptions'!$D$70:$D$98,'Inputs & Assumptions'!$D$104+10+1),0) -> 499783.2 | O8: =IF(('Inputs & Assumptions'!$D$104+11)<='Inputs & Assumptions'!$C$13,INDEX('Inputs & Assumptions'!$D$70:$D$98,'Inputs & Assumptions'!$D$104+11+1),0) -> 484789.71 | P8: =IF(('Inputs & Assumptions'!$D$104+12)<='Inputs & Assumptions'!$C$13,INDEX('Inputs & Assumptions'!$D$70:$D$98,'Inputs & Assumptions'!$D$104+12+1),0) -> 470246.02 | Q8: =IF(('Inputs & Assumptions'!$D$104+13)<='Inputs & Assumptions'!$C$13,INDEX('Inputs & Assumptions'!$D$70:$D$98,'Inputs & Assumptions'!$D$104+13+1),0) -> 456138.64 | R8: =IF(('Inputs & Assumptions'!$D$104+14)<='Inputs & Assumptions'!$C$13,INDEX('Inputs & Assumptions'!$D$70:$D$98,'Inputs & Assumptions'!$D$104+14+1),0) -> 442454.48 | S8: =IF(('Inputs & Assumptions'!$D$104+15)<='Inputs & Assumptions'!$C$13,INDEX('Inputs & Assumptions'!$D$70:$D$98,'Inputs & Assumptions'!$D$104+15+1),0) -> 429180.84 | T8: =IF(('Inputs & Assumptions'!$D$104+16)<='Inputs & Assumptions'!$C$13,INDEX('Inputs & Assumptions'!$D$70:$D$98,'Inputs & Assumptions'!$D$104+16+1),0) -> 416305.42 | U8: =IF(('Inputs & Assumptions'!$D$104+17)<='Inputs & Assumptions'!$C$13,INDEX('Inputs & Assumptions'!$D$70:$D$98,'Inputs & Assumptions'!$D$104+17+1),0) -> 403816.25 | V8: =IF(('Inputs & Assumptions'!$D$104+18)<='Inputs & Assumptions'!$C$13,INDEX('Inputs & Assumptions'!$D$70:$D$98,'Inputs & Assumptions'!$D$104+18+1),0) -> 391701.77 | W8: =IF(('Inputs & Assumptions'!$D$104+19)<='Inputs & Assumptions'!$C$13,INDEX('Inputs & Assumptions'!$D$70:$D$98,'Inputs & Assumptions'!$D$104+19+1),0) -> 379950.71 | X8: =IF(('Inputs & Assumptions'!$D$104+20)<='Inputs & Assumptions'!$C$13,INDEX('Inputs & Assumptions'!$D$70:$D$98,'Inputs & Assumptions'!$D$104+20+1),0) -> 368552.19 | Y8: =IF(('Inputs & Assumptions'!$D$104+21)<='Inputs & Assumptions'!$C$13,INDEX('Inputs & Assumptions'!$D$70:$D$98,'Inputs & Assumptions'!$D$104+21+1),0) -> 357495.63 | Z8: =IF(('Inputs & Assumptions'!$D$104+22)<='Inputs & Assumptions'!$C$13,INDEX('Inputs & Assumptions'!$D$70:$D$98,'Inputs & Assumptions'!$D$104+22+1),0) -> 346770.76 | AA8: =IF(('Inputs & Assumptions'!$D$104+23)<='Inputs & Assumptions'!$C$13,INDEX('Inputs & Assumptions'!$D$70:$D$98,'Inputs & Assumptions'!$D$104+23+1),0) -> 336367.63 | AB8: =IF(('Inputs & Assumptions'!$D$104+24)<='Inputs & Assumptions'!$C$13,INDEX('Inputs & Assumptions'!$D$70:$D$98,'Inputs & Assumptions'!$D$104+24+1),0) -> 326276.61 | AC8: =IF(('Inputs & Assumptions'!$D$104+25)<='Inputs & Assumptions'!$C$13,INDEX('Inputs & Assumptions'!$D$70:$D$98,'Inputs & Assumptions'!$D$104+25+1),0) -> 316488.31 | AD8: =IF(('Inputs & Assumptions'!$D$104+26)<='Inputs & Assumptions'!$C$13,INDEX('Inputs & Assumptions'!$D$70:$D$98,'Inputs & Assumptions'!$D$104+26+1),0) -> 306993.66 | AE8: =IF(('Inputs & Assumptions'!$D$104+27)<='Inputs & Assumptions'!$C$13,INDEX('Inputs & Assumptions'!$D$70:$D$98,'Inputs & Assumptions'!$D$104+27+1),0) -> 9926128.3 | AF8: =IF(('Inputs & Assumptions'!$D$104+28)<='Inputs & Assumptions'!$C$13,INDEX('Inputs & Assumptions'!$D$70:$D$98,'Inputs & Assumptions'!$D$104+28+1),0) -> 0 | AG8: =IF(('Inputs & Assumptions'!$D$104+29)<='Inputs & Assumptions'!$C$13,INDEX('Inputs & Assumptions'!$D$70:$D$98,'Inputs & Assumptions'!$D$104+29+1),0) -> 0 | AH8: =IF(('Inputs & Assumptions'!$D$104+30)<='Inputs & Assumptions'!$C$13,INDEX('Inputs & Assumptions'!$D$70:$D$98,'Inputs & Assumptions'!$D$104+30+1),0) -> 0 | AI8: =IF(('Inputs & Assumptions'!$D$104+31)<='Inputs & Assumptions'!$C$13,INDEX('Inputs & Assumptions'!$D$70:$D$98,'Inputs & Assumptions'!$D$104+31+1),0) -> 0 | AJ8: =IF(('Inputs & Assumptions'!$D$104+32)<='Inputs & Assumptions'!$C$13,INDEX('Inputs & Assumptions'!$D$70:$D$98,'Inputs & Assumptions'!$D$104+32+1),0) -> 0 | AK8: =IF(('Inputs & Assumptions'!$D$104+33)<='Inputs & Assumptions'!$C$13,INDEX('Inputs & Assumptions'!$D$70:$D$98,'Inputs & Assumptions'!$D$104+33+1),0) -> 0 | AL8: =IF(('Inputs & Assumptions'!$D$104+34)<='Inputs & Assumptions'!$C$13,INDEX('Inputs & Assumptions'!$D$70:$D$98,'Inputs & Assumptions'!$D$104+34+1),0) -> 0 | AM8: =IF(('Inputs & Assumptions'!$D$104+35)<='Inputs & Assumptions'!$C$13,INDEX('Inputs & Assumptions'!$D$70:$D$98,'Inputs & Assumptions'!$D$104+35+1),0) -> 0 | AN8: =IF(('Inputs & Assumptions'!$D$104+36)<='Inputs & Assumptions'!$C$13,INDEX('Inputs & Assumptions'!$D$70:$D$98,'Inputs & Assumptions'!$D$104+36+1),0) -> 0
B9: ='Inputs & Assumptions'!$B$105 -> 4 | E9: =IF(('Inputs & Assumptions'!$D$105+1)<='Inputs & Assumptions'!$C$13,INDEX('Inputs & Assumptions'!$D$70:$D$98,'Inputs & Assumptions'!$D$105+1+1),0) -> 0 | F9: =IF(('Inputs & Assumptions'!$D$105+2)<='Inputs & Assumptions'!$C$13,INDEX('Inputs & Assumptions'!$D$70:$D$98,'Inputs & Assumptions'!$D$105+2+1),0) -> 0 | G9: =IF(('Inputs & Assumptions'!$D$105+3)<='Inputs & Assumptions'!$C$13,INDEX('Inputs & Assumptions'!$D$70:$D$98,'Inputs & Assumptions'!$D$105+3+1),0) -> 0 | H9: =IF(('Inputs & Assumptions'!$D$105+4)<='Inputs & Assumptions'!$C$13,INDEX('Inputs & Assumptions'!$D$70:$D$98,'Inputs & Assumptions'!$D$105+4+1),0) -> 600000 | I9: =IF(('Inputs & Assumptions'!$D$105+5)<='Inputs & Assumptions'!$C$13,INDEX('Inputs & Assumptions'!$D$70:$D$98,'Inputs & Assumptions'!$D$105+5+1),0) -> 582000 | J9: =IF(('Inputs & Assumptions'!$D$105+6)<='Inputs & Assumptions'!$C$13,INDEX('Inputs & Assumptions'!$D$70:$D$98,'Inputs & Assumptions'!$D$105+6+1),0) -> 564540 | K9: =IF(('Inputs & Assumptions'!$D$105+7)<='Inputs & Assumptions'!$C$13,INDEX('Inputs & Assumptions'!$D$70:$D$98,'Inputs & Assumptions'!$D$105+7+1),0) -> 547603.8 | L9: =IF(('Inputs & Assumptions'!$D$105+8)<='Inputs & Assumptions'!$C$13,INDEX('Inputs & Assumptions'!$D$70:$D$98,'Inputs & Assumptions'!$D$105+8+1),0) -> 531175.69 | M9: =IF(('Inputs & Assumptions'!$D$105+9)<='Inputs & Assumptions'!$C$13,INDEX('Inputs & Assumptions'!$D$70:$D$98,'Inputs & Assumptions'!$D$105+9+1),0) -> 515240.42 | N9: =IF(('Inputs & Assumptions'!$D$105+10)<='Inputs & Assumptions'!$C$13,INDEX('Inputs & Assumptions'!$D$70:$D$98,'Inputs & Assumptions'!$D$105+10+1),0) -> 499783.2 | O9: =IF(('Inputs & Assumptions'!$D$105+11)<='Inputs & Assumptions'!$C$13,INDEX('Inputs & Assumptions'!$D$70:$D$98,'Inputs & Assumptions'!$D$105+11+1),0) -> 484789.71 | P9: =IF(('Inputs & Assumptions'!$D$105+12)<='Inputs & Assumptions'!$C$13,INDEX('Inputs & Assumptions'!$D$70:$D$98,'Inputs & Assumptions'!$D$105+12+1),0) -> 470246.02 | Q9: =IF(('Inputs & Assumptions'!$D$105+13)<='Inputs & Assumptions'!$C$13,INDEX('Inputs & Assumptions'!$D$70:$D$98,'Inputs & Assumptions'!$D$105+13+1),0) -> 456138.64 | R9: =IF(('Inputs & Assumptions'!$D$105+14)<='Inputs & Assumptions'!$C$13,INDEX('Inputs & Assumptions'!$D$70:$D$98,'Inputs & Assumptions'!$D$105+14+1),0) -> 442454.48 | S9: =IF(('Inputs & Assumptions'!$D$105+15)<='Inputs & Assumptions'!$C$13,INDEX('Inputs & Assumptions'!$D$70:$D$98,'Inputs & Assumptions'!$D$105+15+1),0) -> 429180.84 | T9: =IF(('Inputs & Assumptions'!$D$105+16)<='Inputs & Assumptions'!$C$13,INDEX('Inputs & Assumptions'!$D$70:$D$98,'Inputs & Assumptions'!$D$105+16+1),0) -> 416305.42 | U9: =IF(('Inputs & Assumptions'!$D$105+17)<='Inputs & Assumptions'!$C$13,INDEX('Inputs & Assumptions'!$D$70:$D$98,'Inputs & Assumptions'!$D$105+17+1),0) -> 403816.25 | V9: =IF(('Inputs & Assumptions'!$D$105+18)<='Inputs & Assumptions'!$C$13,INDEX('Inputs & Assumptions'!$D$70:$D$98,'Inputs & Assumptions'!$D$105+18+1),0) -> 391701.77 | W9: =IF(('Inputs & Assumptions'!$D$105+19)<='Inputs & Assumptions'!$C$13,INDEX('Inputs & Assumptions'!$D$70:$D$98,'Inputs & Assumptions'!$D$105+19+1),0) -> 379950.71 | X9: =IF(('Inputs & Assumptions'!$D$105+20)<='Inputs & Assumptions'!$C$13,INDEX('Inputs & Assumptions'!$D$70:$D$98,'Inputs & Assumptions'!$D$105+20+1),0) -> 368552.19 | Y9: =IF(('Inputs & Assumptions'!$D$105+21)<='Inputs & Assumptions'!$C$13,INDEX('Inputs & Assumptions'!$D$70:$D$98,'Inputs & Assumptions'!$D$105+21+1),0) -> 357495.63 | Z9: =IF(('Inputs & Assumptions'!$D$105+22)<='Inputs & Assumptions'!$C$13,INDEX('Inputs & Assumptions'!$D$70:$D$98,'Inputs & Assumptions'!$D$105+22+1),0) -> 346770.76 | AA9: =IF(('Inputs & Assumptions'!$D$105+23)<='Inputs & Assumptions'!$C$13,INDEX('Inputs & Assumptions'!$D$70:$D$98,'Inputs & Assumptions'!$D$105+23+1),0) -> 336367.63 | AB9: =IF(('Inputs & Assumptions'!$D$105+24)<='Inputs & Assumptions'!$C$13,INDEX('Inputs & Assumptions'!$D$70:$D$98,'Inputs & Assumptions'!$D$105+24+1),0) -> 326276.61 | AC9: =IF(('Inputs & Assumptions'!$D$105+25)<='Inputs & Assumptions'!$C$13,INDEX('Inputs & Assumptions'!$D$70:$D$98,'Inputs & Assumptions'!$D$105+25+1),0) -> 316488.31 | AD9: =IF(('Inputs & Assumptions'!$D$105+26)<='Inputs & Assumptions'!$C$13,INDEX('Inputs & Assumptions'!$D$70:$D$98,'Inputs & Assumptions'!$D$105+26+1),0) -> 306993.66 | AE9: =IF(('Inputs & Assumptions'!$D$105+27)<='Inputs & Assumptions'!$C$13,INDEX('Inputs & Assumptions'!$D$70:$D$98,'Inputs & Assumptions'!$D$105+27+1),0) -> 9926128.3 | AF9: =IF(('Inputs & Assumptions'!$D$105+28)<='Inputs & Assumptions'!$C$13,INDEX('Inputs & Assumptions'!$D$70:$D$98,'Inputs & Assumptions'!$D$105+28+1),0) -> 0 | AG9: =IF(('Inputs & Assumptions'!$D$105+29)<='Inputs & Assumptions'!$C$13,INDEX('Inputs & Assumptions'!$D$70:$D$98,'Inputs & Assumptions'!$D$105+29+1),0) -> 0 | AH9: =IF(('Inputs & Assumptions'!$D$105+30)<='Inputs & Assumptions'!$C$13,INDEX('Inputs & Assumptions'!$D$70:$D$98,'Inputs & Assumptions'!$D$105+30+1),0) -> 0 | AI9: =IF(('Inputs & Assumptions'!$D$105+31)<='Inputs & Assumptions'!$C$13,INDEX('Inputs & Assumptions'!$D$70:$D$98,'Inputs & Assumptions'!$D$105+31+1),0) -> 0 | AJ9: =IF(('Inputs & Assumptions'!$D$105+32)<='Inputs & Assumptions'!$C$13,INDEX('Inputs & Assumptions'!$D$70:$D$98,'Inputs & Assumptions'!$D$105+32+1),0) -> 0 | AK9: =IF(('Inputs & Assumptions'!$D$105+33)<='Inputs & Assumptions'!$C$13,INDEX('Inputs & Assumptions'!$D$70:$D$98,'Inputs & Assumptions'!$D$105+33+1),0) -> 0 | AL9: =IF(('Inputs & Assumptions'!$D$105+34)<='Inputs & Assumptions'!$C$13,INDEX('Inputs & Assumptions'!$D$70:$D$98,'Inputs & Assumptions'!$D$105+34+1),0) -> 0 | AM9: =IF(('Inputs & Assumptions'!$D$105+35)<='Inputs & Assumptions'!$C$13,INDEX('Inputs & Assumptions'!$D$70:$D$98,'Inputs & Assumptions'!$D$105+35+1),0) -> 0 | AN9: =IF(('Inputs & Assumptions'!$D$105+36)<='Inputs & Assumptions'!$C$13,INDEX('Inputs & Assumptions'!$D$70:$D$98,'Inputs & Assumptions'!$D$105+36+1),0) -> 0
B10: ='Inputs & Assumptions'!$B$106 -> 5 | E10: =IF(('Inputs & Assumptions'!$D$106+1)<='Inputs & Assumptions'!$C$13,INDEX('Inputs & Assumptions'!$D$70:$D$98,'Inputs & Assumptions'!$D$106+1+1),0) -> 0 | F10: =IF(('Inputs & Assumptions'!$D$106+2)<='Inputs & Assumptions'!$C$13,INDEX('Inputs & Assumptions'!$D$70:$D$98,'Inputs & Assumptions'!$D$106+2+1),0) -> 0 | G10: =IF(('Inputs & Assumptions'!$D$106+3)<='Inputs & Assumptions'!$C$13,INDEX('Inputs & Assumptions'!$D$70:$D$98,'Inputs & Assumptions'!$D$106+3+1),0) -> 600000 | H10: =IF(('Inputs & Assumptions'!$D$106+4)<='Inputs & Assumptions'!$C$13,INDEX('Inputs & Assumptions'!$D$70:$D$98,'Inputs & Assumptions'!$D$106+4+1),0) -> 582000 | I10: =IF(('Inputs & Assumptions'!$D$106+5)<='Inputs & Assumptions'!$C$13,INDEX('Inputs & Assumptions'!$D$70:$D$98,'Inputs & Assumptions'!$D$106+5+1),0) -> 564540 | J10: =IF(('Inputs & Assumptions'!$D$106+6)<='Inputs & Assumptions'!$C$13,INDEX('Inputs & Assumptions'!$D$70:$D$98,'Inputs & Assumptions'!$D$106+6+1),0) -> 547603.8 | K10: =IF(('Inputs & Assumptions'!$D$106+7)<='Inputs & Assumptions'!$C$13,INDEX('Inputs & Assumptions'!$D$70:$D$98,'Inputs & Assumptions'!$D$106+7+1),0) -> 531175.69 | L10: =IF(('Inputs & Assumptions'!$D$106+8)<='Inputs & Assumptions'!$C$13,INDEX('Inputs & Assumptions'!$D$70:$D$98,'Inputs & Assumptions'!$D$106+8+1),0) -> 515240.42 | M10: =IF(('Inputs & Assumptions'!$D$106+9)<='Inputs & Assumptions'!$C$13,INDEX('Inputs & Assumptions'!$D$70:$D$98,'Inputs & Assumptions'!$D$106+9+1),0) -> 499783.2 | N10: =IF(('Inputs & Assumptions'!$D$106+10)<='Inputs & Assumptions'!$C$13,INDEX('Inputs & Assumptions'!$D$70:$D$98,'Inputs & Assumptions'!$D$106+10+1),0) -> 484789.71 | O10: =IF(('Inputs & Assumptions'!$D$106+11)<='Inputs & Assumptions'!$C$13,INDEX('Inputs & Assumptions'!$D$70:$D$98,'Inputs & Assumptions'!$D$106+11+1),0) -> 470246.02 | P10: =IF(('Inputs & Assumptions'!$D$106+12)<='Inputs & Assumptions'!$C$13,INDEX('Inputs & Assumptions'!$D$70:$D$98,'Inputs & Assumptions'!$D$106+12+1),0) -> 456138.64 | Q10: =IF(('Inputs & Assumptions'!$D$106+13)<='Inputs & Assumptions'!$C$13,INDEX('Inputs & Assumptions'!$D$70:$D$98,'Inputs & Assumptions'!$D$106+13+1),0) -> 442454.48 | R10: =IF(('Inputs & Assumptions'!$D$106+14)<='Inputs & Assumptions'!$C$13,INDEX('Inputs & Assumptions'!$D$70:$D$98,'Inputs & Assumptions'!$D$106+14+1),0) -> 429180.84 | S10: =IF(('Inputs & Assumptions'!$D$106+15)<='Inputs & Assumptions'!$C$13,INDEX('Inputs & Assumptions'!$D$70:$D$98,'Inputs & Assumptions'!$D$106+15+1),0) -> 416305.42 | T10: =IF(('Inputs & Assumptions'!$D$106+16)<='Inputs & Assumptions'!$C$13,INDEX('Inputs & Assumptions'!$D$70:$D$98,'Inputs & Assumptions'!$D$106+16+1),0) -> 403816.25 | U10: =IF(('Inputs & Assumptions'!$D$106+17)<='Inputs & Assumptions'!$C$13,INDEX('Inputs & Assumptions'!$D$70:$D$98,'Inputs & Assumptions'!$D$106+17+1),0) -> 391701.77 | V10: =IF(('Inputs & Assumptions'!$D$106+18)<='Inputs & Assumptions'!$C$13,INDEX('Inputs & Assumptions'!$D$70:$D$98,'Inputs & Assumptions'!$D$106+18+1),0) -> 379950.71 | W10: =IF(('Inputs & Assumptions'!$D$106+19)<='Inputs & Assumptions'!$C$13,INDEX('Inputs & Assumptions'!$D$70:$D$98,'Inputs & Assumptions'!$D$106+19+1),0) -> 368552.19 | X10: =IF(('Inputs & Assumptions'!$D$106+20)<='Inputs & Assumptions'!$C$13,INDEX('Inputs & Assumptions'!$D$70:$D$98,'Inputs & Assumptions'!$D$106+20+1),0) -> 357495.63 | Y10: =IF(('Inputs & Assumptions'!$D$106+21)<='Inputs & Assumptions'!$C$13,INDEX('Inputs & Assumptions'!$D$70:$D$98,'Inputs & Assumptions'!$D$106+21+1),0) -> 346770.76 | Z10: =IF(('Inputs & Assumptions'!$D$106+22)<='Inputs & Assumptions'!$C$13,INDEX('Inputs & Assumptions'!$D$70:$D$98,'Inputs & Assumptions'!$D$106+22+1),0) -> 336367.63 | AA10: =IF(('Inputs & Assumptions'!$D$106+23)<='Inputs & Assumptions'!$C$13,INDEX('Inputs & Assumptions'!$D$70:$D$98,'Inputs & Assumptions'!$D$106+23+1),0) -> 326276.61 | AB10: =IF(('Inputs & Assumptions'!$D$106+24)<='Inputs & Assumptions'!$C$13,INDEX('Inputs & Assumptions'!$D$70:$D$98,'Inputs & Assumptions'!$D$106+24+1),0) -> 316488.31 | AC10: =IF(('Inputs & Assumptions'!$D$106+25)<='Inputs & Assumptions'!$C$13,INDEX('Inputs & Assumptions'!$D$70:$D$98,'Inputs & Assumptions'!$D$106+25+1),0) -> 306993.66 | AD10: =IF(('Inputs & Assumptions'!$D$106+26)<='Inputs & Assumptions'!$C$13,INDEX('Inputs & Assumptions'!$D$70:$D$98,'Inputs & Assumptions'!$D$106+26+1),0) -> 9926128.3 | AE10: =IF(('Inputs & Assumptions'!$D$106+27)<='Inputs & Assumptions'!$C$13,INDEX('Inputs & Assumptions'!$D$70:$D$98,'Inputs & Assumptions'!$D$106+27+1),0) -> 0 | AF10: =IF(('Inputs & Assumptions'!$D$106+28)<='Inputs & Assumptions'!$C$13,INDEX('Inputs & Assumptions'!$D$70:$D$98,'Inputs & Assumptions'!$D$106+28+1),0) -> 0 | AG10: =IF(('Inputs & Assumptions'!$D$106+29)<='Inputs & Assumptions'!$C$13,INDEX('Inputs & Assumptions'!$D$70:$D$98,'Inputs & Assumptions'!$D$106+29+1),0) -> 0 | AH10: =IF(('Inputs & Assumptions'!$D$106+30)<='Inputs & Assumptions'!$C$13,INDEX('Inputs & Assumptions'!$D$70:$D$98,'Inputs & Assumptions'!$D$106+30+1),0) -> 0 | AI10: =IF(('Inputs & Assumptions'!$D$106+31)<='Inputs & Assumptions'!$C$13,INDEX('Inputs & Assumptions'!$D$70:$D$98,'Inputs & Assumptions'!$D$106+31+1),0) -> 0 | AJ10: =IF(('Inputs & Assumptions'!$D$106+32)<='Inputs & Assumptions'!$C$13,INDEX('Inputs & Assumptions'!$D$70:$D$98,'Inputs & Assumptions'!$D$106+32+1),0) -> 0 | AK10: =IF(('Inputs & Assumptions'!$D$106+33)<='Inputs & Assumptions'!$C$13,INDEX('Inputs & Assumptions'!$D$70:$D$98,'Inputs & Assumptions'!$D$106+33+1),0) -> 0 | AL10: =IF(('Inputs & Assumptions'!$D$106+34)<='Inputs & Assumptions'!$C$13,INDEX('Inputs & Assumptions'!$D$70:$D$98,'Inputs & Assumptions'!$D$106+34+1),0) -> 0 | AM10: =IF(('Inputs & Assumptions'!$D$106+35)<='Inputs & Assumptions'!$C$13,INDEX('Inputs & Assumptions'!$D$70:$D$98,'Inputs & Assumptions'!$D$106+35+1),0) -> 0 | AN10: =IF(('Inputs & Assumptions'!$D$106+36)<='Inputs & Assumptions'!$C$13,INDEX('Inputs & Assumptions'!$D$70:$D$98,'Inputs & Assumptions'!$D$106+36+1),0) -> 0
B11: ='Inputs & Assumptions'!$B$107 -> 6 | E11: =IF(('Inputs & Assumptions'!$D$107+1)<='Inputs & Assumptions'!$C$13,INDEX('Inputs & Assumptions'!$D$70:$D$98,'Inputs & Assumptions'!$D$107+1+1),0) -> 0 | F11: =IF(('Inputs & Assumptions'!$D$107+2)<='Inputs & Assumptions'!$C$13,INDEX('Inputs & Assumptions'!$D$70:$D$98,'Inputs & Assumptions'!$D$107+2+1),0) -> 0 | G11: =IF(('Inputs & Assumptions'!$D$107+3)<='Inputs & Assumptions'!$C$13,INDEX('Inputs & Assumptions'!$D$70:$D$98,'Inputs & Assumptions'!$D$107+3+1),0) -> 600000 | H11: =IF(('Inputs & Assumptions'!$D$107+4)<='Inputs & Assumptions'!$C$13,INDEX('Inputs & Assumptions'!$D$70:$D$98,'Inputs & Assumptions'!$D$107+4+1),0) -> 582000 | I11: =IF(('Inputs & Assumptions'!$D$107+5)<='Inputs & Assumptions'!$C$13,INDEX('Inputs & Assumptions'!$D$70:$D$98,'Inputs & Assumptions'!$D$107+5+1),0) -> 564540 | J11: =IF(('Inputs & Assumptions'!$D$107+6)<='Inputs & Assumptions'!$C$13,INDEX('Inputs & Assumptions'!$D$70:$D$98,'Inputs & Assumptions'!$D$107+6+1),0) -> 547603.8 | K11: =IF(('Inputs & Assumptions'!$D$107+7)<='Inputs & Assumptions'!$C$13,INDEX('Inputs & Assumptions'!$D$70:$D$98,'Inputs & Assumptions'!$D$107+7+1),0) -> 531175.69 | L11: =IF(('Inputs & Assumptions'!$D$107+8)<='Inputs & Assumptions'!$C$13,INDEX('Inputs & Assumptions'!$D$70:$D$98,'Inputs & Assumptions'!$D$107+8+1),0) -> 515240.42 | M11: =IF(('Inputs & Assumptions'!$D$107+9)<='Inputs & Assumptions'!$C$13,INDEX('Inputs & Assumptions'!$D$70:$D$98,'Inputs & Assumptions'!$D$107+9+1),0) -> 499783.2 | N11: =IF(('Inputs & Assumptions'!$D$107+10)<='Inputs & Assumptions'!$C$13,INDEX('Inputs & Assumptions'!$D$70:$D$98,'Inputs & Assumptions'!$D$107+10+1),0) -> 484789.71 | O11: =IF(('Inputs & Assumptions'!$D$107+11)<='Inputs & Assumptions'!$C$13,INDEX('Inputs & Assumptions'!$D$70:$D$98,'Inputs & Assumptions'!$D$107+11+1),0) -> 470246.02 | P11: =IF(('Inputs & Assumptions'!$D$107+12)<='Inputs & Assumptions'!$C$13,INDEX('Inputs & Assumptions'!$D$70:$D$98,'Inputs & Assumptions'!$D$107+12+1),0) -> 456138.64 | Q11: =IF(('Inputs & Assumptions'!$D$107+13)<='Inputs & Assumptions'!$C$13,INDEX('Inputs & Assumptions'!$D$70:$D$98,'Inputs & Assumptions'!$D$107+13+1),0) -> 442454.48 | R11: =IF(('Inputs & Assumptions'!$D$107+14)<='Inputs & Assumptions'!$C$13,INDEX('Inputs & Assumptions'!$D$70:$D$98,'Inputs & Assumptions'!$D$107+14+1),0) -> 429180.84 | S11: =IF(('Inputs & Assumptions'!$D$107+15)<='Inputs & Assumptions'!$C$13,INDEX('Inputs & Assumptions'!$D$70:$D$98,'Inputs & Assumptions'!$D$107+15+1),0) -> 416305.42 | T11: =IF(('Inputs & Assumptions'!$D$107+16)<='Inputs & Assumptions'!$C$13,INDEX('Inputs & Assumptions'!$D$70:$D$98,'Inputs & Assumptions'!$D$107+16+1),0) -> 403816.25 | U11: =IF(('Inputs & Assumptions'!$D$107+17)<='Inputs & Assumptions'!$C$13,INDEX('Inputs & Assumptions'!$D$70:$D$98,'Inputs & Assumptions'!$D$107+17+1),0) -> 391701.77 | V11: =IF(('Inputs & Assumptions'!$D$107+18)<='Inputs & Assumptions'!$C$13,INDEX('Inputs & Assumptions'!$D$70:$D$98,'Inputs & Assumptions'!$D$107+18+1),0) -> 379950.71 | W11: =IF(('Inputs & Assumptions'!$D$107+19)<='Inputs & Assumptions'!$C$13,INDEX('Inputs & Assumptions'!$D$70:$D$98,'Inputs & Assumptions'!$D$107+19+1),0) -> 368552.19 | X11: =IF(('Inputs & Assumptions'!$D$107+20)<='Inputs & Assumptions'!$C$13,INDEX('Inputs & Assumptions'!$D$70:$D$98,'Inputs & Assumptions'!$D$107+20+1),0) -> 357495.63 | Y11: =IF(('Inputs & Assumptions'!$D$107+21)<='Inputs & Assumptions'!$C$13,INDEX('Inputs & Assumptions'!$D$70:$D$98,'Inputs & Assumptions'!$D$107+21+1),0) -> 346770.76 | Z11: =IF(('Inputs & Assumptions'!$D$107+22)<='Inputs & Assumptions'!$C$13,INDEX('Inputs & Assumptions'!$D$70:$D$98,'Inputs & Assumptions'!$D$107+22+1),0) -> 336367.63 | AA11: =IF(('Inputs & Assumptions'!$D$107+23)<='Inputs & Assumptions'!$C$13,INDEX('Inputs & Assumptions'!$D$70:$D$98,'Inputs & Assumptions'!$D$107+23+1),0) -> 326276.61 | AB11: =IF(('Inputs & Assumptions'!$D$107+24)<='Inputs & Assumptions'!$C$13,INDEX('Inputs & Assumptions'!$D$70:$D$98,'Inputs & Assumptions'!$D$107+24+1),0) -> 316488.31 | AC11: =IF(('Inputs & Assumptions'!$D$107+25)<='Inputs & Assumptions'!$C$13,INDEX('Inputs & Assumptions'!$D$70:$D$98,'Inputs & Assumptions'!$D$107+25+1),0) -> 306993.66 | AD11: =IF(('Inputs & Assumptions'!$D$107+26)<='Inputs & Assumptions'!$C$13,INDEX('Inputs & Assumptions'!$D$70:$D$98,'Inputs & Assumptions'!$D$107+26+1),0) -> 9926128.3 | AE11: =IF(('Inputs & Assumptions'!$D$107+27)<='Inputs & Assumptions'!$C$13,INDEX('Inputs & Assumptions'!$D$70:$D$98,'Inputs & Assumptions'!$D$107+27+1),0) -> 0 | AF11: =IF(('Inputs & Assumptions'!$D$107+28)<='Inputs & Assumptions'!$C$13,INDEX('Inputs & Assumptions'!$D$70:$D$98,'Inputs & Assumptions'!$D$107+28+1),0) -> 0 | AG11: =IF(('Inputs & Assumptions'!$D$107+29)<='Inputs & Assumptions'!$C$13,INDEX('Inputs & Assumptions'!$D$70:$D$98,'Inputs & Assumptions'!$D$107+29+1),0) -> 0 | AH11: =IF(('Inputs & Assumptions'!$D$107+30)<='Inputs & Assumptions'!$C$13,INDEX('Inputs & Assumptions'!$D$70:$D$98,'Inputs & Assumptions'!$D$107+30+1),0) -> 0 | AI11: =IF(('Inputs & Assumptions'!$D$107+31)<='Inputs & Assumptions'!$C$13,INDEX('Inputs & Assumptions'!$D$70:$D$98,'Inputs & Assumptions'!$D$107+31+1),0) -> 0 | AJ11: =IF(('Inputs & Assumptions'!$D$107+32)<='Inputs & Assumptions'!$C$13,INDEX('Inputs & Assumptions'!$D$70:$D$98,'Inputs & Assumptions'!$D$107+32+1),0) -> 0 | AK11: =IF(('Inputs & Assumptions'!$D$107+33)<='Inputs & Assumptions'!$C$13,INDEX('Inputs & Assumptions'!$D$70:$D$98,'Inputs & Assumptions'!$D$107+33+1),0) -> 0 | AL11: =IF(('Inputs & Assumptions'!$D$107+34)<='Inputs & Assumptions'!$C$13,INDEX('Inputs & Assumptions'!$D$70:$D$98,'Inputs & Assumptions'!$D$107+34+1),0) -> 0 | AM11: =IF(('Inputs & Assumptions'!$D$107+35)<='Inputs & Assumptions'!$C$13,INDEX('Inputs & Assumptions'!$D$70:$D$98,'Inputs & Assumptions'!$D$107+35+1),0) -> 0 | AN11: =IF(('Inputs & Assumptions'!$D$107+36)<='Inputs & Assumptions'!$C$13,INDEX('Inputs & Assumptions'!$D$70:$D$98,'Inputs & Assumptions'!$D$107+36+1),0) -> 0
B12: ='Inputs & Assumptions'!$B$108 -> 7 | E12: =IF(('Inputs & Assumptions'!$D$108+1)<='Inputs & Assumptions'!$C$13,INDEX('Inputs & Assumptions'!$D$70:$D$98,'Inputs & Assumptions'!$D$108+1+1),0) -> 0 | F12: =IF(('Inputs & Assumptions'!$D$108+2)<='Inputs & Assumptions'!$C$13,INDEX('Inputs & Assumptions'!$D$70:$D$98,'Inputs & Assumptions'!$D$108+2+1),0) -> 0 | G12: =IF(('Inputs & Assumptions'!$D$108+3)<='Inputs & Assumptions'!$C$13,INDEX('Inputs & Assumptions'!$D$70:$D$98,'Inputs & Assumptions'!$D$108+3+1),0) -> 600000 | H12: =IF(('Inputs & Assumptions'!$D$108+4)<='Inputs & Assumptions'!$C$13,INDEX('Inputs & Assumptions'!$D$70:$D$98,'Inputs & Assumptions'!$D$108+4+1),0) -> 582000 | I12: =IF(('Inputs & Assumptions'!$D$108+5)<='Inputs & Assumptions'!$C$13,INDEX('Inputs & Assumptions'!$D$70:$D$98,'Inputs & Assumptions'!$D$108+5+1),0) -> 564540 | J12: =IF(('Inputs & Assumptions'!$D$108+6)<='Inputs & Assumptions'!$C$13,INDEX('Inputs & Assumptions'!$D$70:$D$98,'Inputs & Assumptions'!$D$108+6+1),0) -> 547603.8 | K12: =IF(('Inputs & Assumptions'!$D$108+7)<='Inputs & Assumptions'!$C$13,INDEX('Inputs & Assumptions'!$D$70:$D$98,'Inputs & Assumptions'!$D$108+7+1),0) -> 531175.69 | L12: =IF(('Inputs & Assumptions'!$D$108+8)<='Inputs & Assumptions'!$C$13,INDEX('Inputs & Assumptions'!$D$70:$D$98,'Inputs & Assumptions'!$D$108+8+1),0) -> 515240.42 | M12: =IF(('Inputs & Assumptions'!$D$108+9)<='Inputs & Assumptions'!$C$13,INDEX('Inputs & Assumptions'!$D$70:$D$98,'Inputs & Assumptions'!$D$108+9+1),0) -> 499783.2 | N12: =IF(('Inputs & Assumptions'!$D$108+10)<='Inputs & Assumptions'!$C$13,INDEX('Inputs & Assumptions'!$D$70:$D$98,'Inputs & Assumptions'!$D$108+10+1),0) -> 484789.71 | O12: =IF(('Inputs & Assumptions'!$D$108+11)<='Inputs & Assumptions'!$C$13,INDEX('Inputs & Assumptions'!$D$70:$D$98,'Inputs & Assumptions'!$D$108+11+1),0) -> 470246.02 | P12: =IF(('Inputs & Assumptions'!$D$108+12)<='Inputs & Assumptions'!$C$13,INDEX('Inputs & Assumptions'!$D$70:$D$98,'Inputs & Assumptions'!$D$108+12+1),0) -> 456138.64 | Q12: =IF(('Inputs & Assumptions'!$D$108+13)<='Inputs & Assumptions'!$C$13,INDEX('Inputs & Assumptions'!$D$70:$D$98,'Inputs & Assumptions'!$D$108+13+1),0) -> 442454.48 | R12: =IF(('Inputs & Assumptions'!$D$108+14)<='Inputs & Assumptions'!$C$13,INDEX('Inputs & Assumptions'!$D$70:$D$98,'Inputs & Assumptions'!$D$108+14+1),0) -> 429180.84 | S12: =IF(('Inputs & Assumptions'!$D$108+15)<='Inputs & Assumptions'!$C$13,INDEX('Inputs & Assumptions'!$D$70:$D$98,'Inputs & Assumptions'!$D$108+15+1),0) -> 416305.42 | T12: =IF(('Inputs & Assumptions'!$D$108+16)<='Inputs & Assumptions'!$C$13,INDEX('Inputs & Assumptions'!$D$70:$D$98,'Inputs & Assumptions'!$D$108+16+1),0) -> 403816.25 | U12: =IF(('Inputs & Assumptions'!$D$108+17)<='Inputs & Assumptions'!$C$13,INDEX('Inputs & Assumptions'!$D$70:$D$98,'Inputs & Assumptions'!$D$108+17+1),0) -> 391701.77 | V12: =IF(('Inputs & Assumptions'!$D$108+18)<='Inputs & Assumptions'!$C$13,INDEX('Inputs & Assumptions'!$D$70:$D$98,'Inputs & Assumptions'!$D$108+18+1),0) -> 379950.71 | W12: =IF(('Inputs & Assumptions'!$D$108+19)<='Inputs & Assumptions'!$C$13,INDEX('Inputs & Assumptions'!$D$70:$D$98,'Inputs & Assumptions'!$D$108+19+1),0) -> 368552.19 | X12: =IF(('Inputs & Assumptions'!$D$108+20)<='Inputs & Assumptions'!$C$13,INDEX('Inputs & Assumptions'!$D$70:$D$98,'Inputs & Assumptions'!$D$108+20+1),0) -> 357495.63 | Y12: =IF(('Inputs & Assumptions'!$D$108+21)<='Inputs & Assumptions'!$C$13,INDEX('Inputs & Assumptions'!$D$70:$D$98,'Inputs & Assumptions'!$D$108+21+1),0) -> 346770.76 | Z12: =IF(('Inputs & Assumptions'!$D$108+22)<='Inputs & Assumptions'!$C$13,INDEX('Inputs & Assumptions'!$D$70:$D$98,'Inputs & Assumptions'!$D$108+22+1),0) -> 336367.63 | AA12: =IF(('Inputs & Assumptions'!$D$108+23)<='Inputs & Assumptions'!$C$13,INDEX('Inputs & Assumptions'!$D$70:$D$98,'Inputs & Assumptions'!$D$108+23+1),0) -> 326276.61 | AB12: =IF(('Inputs & Assumptions'!$D$108+24)<='Inputs & Assumptions'!$C$13,INDEX('Inputs & Assumptions'!$D$70:$D$98,'Inputs & Assumptions'!$D$108+24+1),0) -> 316488.31 | AC12: =IF(('Inputs & Assumptions'!$D$108+25)<='Inputs & Assumptions'!$C$13,INDEX('Inputs & Assumptions'!$D$70:$D$98,'Inputs & Assumptions'!$D$108+25+1),0) -> 306993.66 | AD12: =IF(('Inputs & Assumptions'!$D$108+26)<='Inputs & Assumptions'!$C$13,INDEX('Inputs & Assumptions'!$D$70:$D$98,'Inputs & Assumptions'!$D$108+26+1),0) -> 9926128.3 | AE12: =IF(('Inputs & Assumptions'!$D$108+27)<='Inputs & Assumptions'!$C$13,INDEX('Inputs & Assumptions'!$D$70:$D$98,'Inputs & Assumptions'!$D$108+27+1),0) -> 0 | AF12: =IF(('Inputs & Assumptions'!$D$108+28)<='Inputs & Assumptions'!$C$13,INDEX('Inputs & Assumptions'!$D$70:$D$98,'Inputs & Assumptions'!$D$108+28+1),0) -> 0 | AG12: =IF(('Inputs & Assumptions'!$D$108+29)<='Inputs & Assumptions'!$C$13,INDEX('Inputs & Assumptions'!$D$70:$D$98,'Inputs & Assumptions'!$D$108+29+1),0) -> 0 | AH12: =IF(('Inputs & Assumptions'!$D$108+30)<='Inputs & Assumptions'!$C$13,INDEX('Inputs & Assumptions'!$D$70:$D$98,'Inputs & Assumptions'!$D$108+30+1),0) -> 0 | AI12: =IF(('Inputs & Assumptions'!$D$108+31)<='Inputs & Assumptions'!$C$13,INDEX('Inputs & Assumptions'!$D$70:$D$98,'Inputs & Assumptions'!$D$108+31+1),0) -> 0 | AJ12: =IF(('Inputs & Assumptions'!$D$108+32)<='Inputs & Assumptions'!$C$13,INDEX('Inputs & Assumptions'!$D$70:$D$98,'Inputs & Assumptions'!$D$108+32+1),0) -> 0 | AK12: =IF(('Inputs & Assumptions'!$D$108+33)<='Inputs & Assumptions'!$C$13,INDEX('Inputs & Assumptions'!$D$70:$D$98,'Inputs & Assumptions'!$D$108+33+1),0) -> 0 | AL12: =IF(('Inputs & Assumptions'!$D$108+34)<='Inputs & Assumptions'!$C$13,INDEX('Inputs & Assumptions'!$D$70:$D$98,'Inputs & Assumptions'!$D$108+34+1),0) -> 0 | AM12: =IF(('Inputs & Assumptions'!$D$108+35)<='Inputs & Assumptions'!$C$13,INDEX('Inputs & Assumptions'!$D$70:$D$98,'Inputs & Assumptions'!$D$108+35+1),0) -> 0 | AN12: =IF(('Inputs & Assumptions'!$D$108+36)<='Inputs & Assumptions'!$C$13,INDEX('Inputs & Assumptions'!$D$70:$D$98,'Inputs & Assumptions'!$D$108+36+1),0) -> 0
B13: ='Inputs & Assumptions'!$B$109 -> 8 | E13: =IF(('Inputs & Assumptions'!$D$109+1)<='Inputs & Assumptions'!$C$13,INDEX('Inputs & Assumptions'!$D$70:$D$98,'Inputs & Assumptions'!$D$109+1+1),0) -> 0 | F13: =IF(('Inputs & Assumptions'!$D$109+2)<='Inputs & Assumptions'!$C$13,INDEX('Inputs & Assumptions'!$D$70:$D$98,'Inputs & Assumptions'!$D$109+2+1),0) -> 600000 | G13: =IF(('Inputs & Assumptions'!$D$109+3)<='Inputs & Assumptions'!$C$13,INDEX('Inputs & Assumptions'!$D$70:$D$98,'Inputs & Assumptions'!$D$109+3+1),0) -> 582000 | H13: =IF(('Inputs & Assumptions'!$D$109+4)<='Inputs & Assumptions'!$C$13,INDEX('Inputs & Assumptions'!$D$70:$D$98,'Inputs & Assumptions'!$D$109+4+1),0) -> 564540 | I13: =IF(('Inputs & Assumptions'!$D$109+5)<='Inputs & Assumptions'!$C$13,INDEX('Inputs & Assumptions'!$D$70:$D$98,'Inputs & Assumptions'!$D$109+5+1),0) -> 547603.8 | J13: =IF(('Inputs & Assumptions'!$D$109+6)<='Inputs & Assumptions'!$C$13,INDEX('Inputs & Assumptions'!$D$70:$D$98,'Inputs & Assumptions'!$D$109+6+1),0) -> 531175.69 | K13: =IF(('Inputs & Assumptions'!$D$109+7)<='Inputs & Assumptions'!$C$13,INDEX('Inputs & Assumptions'!$D$70:$D$98,'Inputs & Assumptions'!$D$109+7+1),0) -> 515240.42 | L13: =IF(('Inputs & Assumptions'!$D$109+8)<='Inputs & Assumptions'!$C$13,INDEX('Inputs & Assumptions'!$D$70:$D$98,'Inputs & Assumptions'!$D$109+8+1),0) -> 499783.2 | M13: =IF(('Inputs & Assumptions'!$D$109+9)<='Inputs & Assumptions'!$C$13,INDEX('Inputs & Assumptions'!$D$70:$D$98,'Inputs & Assumptions'!$D$109+9+1),0) -> 484789.71 | N13: =IF(('Inputs & Assumptions'!$D$109+10)<='Inputs & Assumptions'!$C$13,INDEX('Inputs & Assumptions'!$D$70:$D$98,'Inputs & Assumptions'!$D$109+10+1),0) -> 470246.02 | O13: =IF(('Inputs & Assumptions'!$D$109+11)<='Inputs & Assumptions'!$C$13,INDEX('Inputs & Assumptions'!$D$70:$D$98,'Inputs & Assumptions'!$D$109+11+1),0) -> 456138.64 | P13: =IF(('Inputs & Assumptions'!$D$109+12)<='Inputs & Assumptions'!$C$13,INDEX('Inputs & Assumptions'!$D$70:$D$98,'Inputs & Assumptions'!$D$109+12+1),0) -> 442454.48 | Q13: =IF(('Inputs & Assumptions'!$D$109+13)<='Inputs & Assumptions'!$C$13,INDEX('Inputs & Assumptions'!$D$70:$D$98,'Inputs & Assumptions'!$D$109+13+1),0) -> 429180.84 | R13: =IF(('Inputs & Assumptions'!$D$109+14)<='Inputs & Assumptions'!$C$13,INDEX('Inputs & Assumptions'!$D$70:$D$98,'Inputs & Assumptions'!$D$109+14+1),0) -> 416305.42 | S13: =IF(('Inputs & Assumptions'!$D$109+15)<='Inputs & Assumptions'!$C$13,INDEX('Inputs & Assumptions'!$D$70:$D$98,'Inputs & Assumptions'!$D$109+15+1),0) -> 403816.25 | T13: =IF(('Inputs & Assumptions'!$D$109+16)<='Inputs & Assumptions'!$C$13,INDEX('Inputs & Assumptions'!$D$70:$D$98,'Inputs & Assumptions'!$D$109+16+1),0) -> 391701.77 | U13: =IF(('Inputs & Assumptions'!$D$109+17)<='Inputs & Assumptions'!$C$13,INDEX('Inputs & Assumptions'!$D$70:$D$98,'Inputs & Assumptions'!$D$109+17+1),0) -> 379950.71 | V13: =IF(('Inputs & Assumptions'!$D$109+18)<='Inputs & Assumptions'!$C$13,INDEX('Inputs & Assumptions'!$D$70:$D$98,'Inputs & Assumptions'!$D$109+18+1),0) -> 368552.19 | W13: =IF(('Inputs & Assumptions'!$D$109+19)<='Inputs & Assumptions'!$C$13,INDEX('Inputs & Assumptions'!$D$70:$D$98,'Inputs & Assumptions'!$D$109+19+1),0) -> 357495.63 | X13: =IF(('Inputs & Assumptions'!$D$109+20)<='Inputs & Assumptions'!$C$13,INDEX('Inputs & Assumptions'!$D$70:$D$98,'Inputs & Assumptions'!$D$109+20+1),0) -> 346770.76 | Y13: =IF(('Inputs & Assumptions'!$D$109+21)<='Inputs & Assumptions'!$C$13,INDEX('Inputs & Assumptions'!$D$70:$D$98,'Inputs & Assumptions'!$D$109+21+1),0) -> 336367.63 | Z13: =IF(('Inputs & Assumptions'!$D$109+22)<='Inputs & Assumptions'!$C$13,INDEX('Inputs & Assumptions'!$D$70:$D$98,'Inputs & Assumptions'!$D$109+22+1),0) -> 326276.61 | AA13: =IF(('Inputs & Assumptions'!$D$109+23)<='Inputs & Assumptions'!$C$13,INDEX('Inputs & Assumptions'!$D$70:$D$98,'Inputs & Assumptions'!$D$109+23+1),0) -> 316488.31 | AB13: =IF(('Inputs & Assumptions'!$D$109+24)<='Inputs & Assumptions'!$C$13,INDEX('Inputs & Assumptions'!$D$70:$D$98,'Inputs & Assumptions'!$D$109+24+1),0) -> 306993.66 | AC13: =IF(('Inputs & Assumptions'!$D$109+25)<='Inputs & Assumptions'!$C$13,INDEX('Inputs & Assumptions'!$D$70:$D$98,'Inputs & Assumptions'!$D$109+25+1),0) -> 9926128.3 | AD13: =IF(('Inputs & Assumptions'!$D$109+26)<='Inputs & Assumptions'!$C$13,INDEX('Inputs & Assumptions'!$D$70:$D$98,'Inputs & Assumptions'!$D$109+26+1),0) -> 0 | AE13: =IF(('Inputs & Assumptions'!$D$109+27)<='Inputs & Assumptions'!$C$13,INDEX('Inputs & Assumptions'!$D$70:$D$98,'Inputs & Assumptions'!$D$109+27+1),0) -> 0 | AF13: =IF(('Inputs & Assumptions'!$D$109+28)<='Inputs & Assumptions'!$C$13,INDEX('Inputs & Assumptions'!$D$70:$D$98,'Inputs & Assumptions'!$D$109+28+1),0) -> 0 | AG13: =IF(('Inputs & Assumptions'!$D$109+29)<='Inputs & Assumptions'!$C$13,INDEX('Inputs & Assumptions'!$D$70:$D$98,'Inputs & Assumptions'!$D$109+29+1),0) -> 0 | AH13: =IF(('Inputs & Assumptions'!$D$109+30)<='Inputs & Assumptions'!$C$13,INDEX('Inputs & Assumptions'!$D$70:$D$98,'Inputs & Assumptions'!$D$109+30+1),0) -> 0 | AI13: =IF(('Inputs & Assumptions'!$D$109+31)<='Inputs & Assumptions'!$C$13,INDEX('Inputs & Assumptions'!$D$70:$D$98,'Inputs & Assumptions'!$D$109+31+1),0) -> 0 | AJ13: =IF(('Inputs & Assumptions'!$D$109+32)<='Inputs & Assumptions'!$C$13,INDEX('Inputs & Assumptions'!$D$70:$D$98,'Inputs & Assumptions'!$D$109+32+1),0) -> 0 | AK13: =IF(('Inputs & Assumptions'!$D$109+33)<='Inputs & Assumptions'!$C$13,INDEX('Inputs & Assumptions'!$D$70:$D$98,'Inputs & Assumptions'!$D$109+33+1),0) -> 0 | AL13: =IF(('Inputs & Assumptions'!$D$109+34)<='Inputs & Assumptions'!$C$13,INDEX('Inputs & Assumptions'!$D$70:$D$98,'Inputs & Assumptions'!$D$109+34+1),0) -> 0 | AM13: =IF(('Inputs & Assumptions'!$D$109+35)<='Inputs & Assumptions'!$C$13,INDEX('Inputs & Assumptions'!$D$70:$D$98,'Inputs & Assumptions'!$D$109+35+1),0) -> 0 | AN13: =IF(('Inputs & Assumptions'!$D$109+36)<='Inputs & Assumptions'!$C$13,INDEX('Inputs & Assumptions'!$D$70:$D$98,'Inputs & Assumptions'!$D$109+36+1),0) -> 0
B14: ='Inputs & Assumptions'!$B$110 -> 9 | E14: =IF(('Inputs & Assumptions'!$D$110+1)<='Inputs & Assumptions'!$C$13,INDEX('Inputs & Assumptions'!$D$70:$D$98,'Inputs & Assumptions'!$D$110+1+1),0) -> 0 | F14: =IF(('Inputs & Assumptions'!$D$110+2)<='Inputs & Assumptions'!$C$13,INDEX('Inputs & Assumptions'!$D$70:$D$98,'Inputs & Assumptions'!$D$110+2+1),0) -> 600000 | G14: =IF(('Inputs & Assumptions'!$D$110+3)<='Inputs & Assumptions'!$C$13,INDEX('Inputs & Assumptions'!$D$70:$D$98,'Inputs & Assumptions'!$D$110+3+1),0) -> 582000 | H14: =IF(('Inputs & Assumptions'!$D$110+4)<='Inputs & Assumptions'!$C$13,INDEX('Inputs & Assumptions'!$D$70:$D$98,'Inputs & Assumptions'!$D$110+4+1),0) -> 564540 | I14: =IF(('Inputs & Assumptions'!$D$110+5)<='Inputs & Assumptions'!$C$13,INDEX('Inputs & Assumptions'!$D$70:$D$98,'Inputs & Assumptions'!$D$110+5+1),0) -> 547603.8 | J14: =IF(('Inputs & Assumptions'!$D$110+6)<='Inputs & Assumptions'!$C$13,INDEX('Inputs & Assumptions'!$D$70:$D$98,'Inputs & Assumptions'!$D$110+6+1),0) -> 531175.69 | K14: =IF(('Inputs & Assumptions'!$D$110+7)<='Inputs & Assumptions'!$C$13,INDEX('Inputs & Assumptions'!$D$70:$D$98,'Inputs & Assumptions'!$D$110+7+1),0) -> 515240.42 | L14: =IF(('Inputs & Assumptions'!$D$110+8)<='Inputs & Assumptions'!$C$13,INDEX('Inputs & Assumptions'!$D$70:$D$98,'Inputs & Assumptions'!$D$110+8+1),0) -> 499783.2 | M14: =IF(('Inputs & Assumptions'!$D$110+9)<='Inputs & Assumptions'!$C$13,INDEX('Inputs & Assumptions'!$D$70:$D$98,'Inputs & Assumptions'!$D$110+9+1),0) -> 484789.71 | N14: =IF(('Inputs & Assumptions'!$D$110+10)<='Inputs & Assumptions'!$C$13,INDEX('Inputs & Assumptions'!$D$70:$D$98,'Inputs & Assumptions'!$D$110+10+1),0) -> 470246.02 | O14: =IF(('Inputs & Assumptions'!$D$110+11)<='Inputs & Assumptions'!$C$13,INDEX('Inputs & Assumptions'!$D$70:$D$98,'Inputs & Assumptions'!$D$110+11+1),0) -> 456138.64 | P14: =IF(('Inputs & Assumptions'!$D$110+12)<='Inputs & Assumptions'!$C$13,INDEX('Inputs & Assumptions'!$D$70:$D$98,'Inputs & Assumptions'!$D$110+12+1),0) -> 442454.48 | Q14: =IF(('Inputs & Assumptions'!$D$110+13)<='Inputs & Assumptions'!$C$13,INDEX('Inputs & Assumptions'!$D$70:$D$98,'Inputs & Assumptions'!$D$110+13+1),0) -> 429180.84 | R14: =IF(('Inputs & Assumptions'!$D$110+14)<='Inputs & Assumptions'!$C$13,INDEX('Inputs & Assumptions'!$D$70:$D$98,'Inputs & Assumptions'!$D$110+14+1),0) -> 416305.42 | S14: =IF(('Inputs & Assumptions'!$D$110+15)<='Inputs & Assumptions'!$C$13,INDEX('Inputs & Assumptions'!$D$70:$D$98,'Inputs & Assumptions'!$D$110+15+1),0) -> 403816.25 | T14: =IF(('Inputs & Assumptions'!$D$110+16)<='Inputs & Assumptions'!$C$13,INDEX('Inputs & Assumptions'!$D$70:$D$98,'Inputs & Assumptions'!$D$110+16+1),0) -> 391701.77 | U14: =IF(('Inputs & Assumptions'!$D$110+17)<='Inputs & Assumptions'!$C$13,INDEX('Inputs & Assumptions'!$D$70:$D$98,'Inputs & Assumptions'!$D$110+17+1),0) -> 379950.71 | V14: =IF(('Inputs & Assumptions'!$D$110+18)<='Inputs & Assumptions'!$C$13,INDEX('Inputs & Assumptions'!$D$70:$D$98,'Inputs & Assumptions'!$D$110+18+1),0) -> 368552.19 | W14: =IF(('Inputs & Assumptions'!$D$110+19)<='Inputs & Assumptions'!$C$13,INDEX('Inputs & Assumptions'!$D$70:$D$98,'Inputs & Assumptions'!$D$110+19+1),0) -> 357495.63 | X14: =IF(('Inputs & Assumptions'!$D$110+20)<='Inputs & Assumptions'!$C$13,INDEX('Inputs & Assumptions'!$D$70:$D$98,'Inputs & Assumptions'!$D$110+20+1),0) -> 346770.76 | Y14: =IF(('Inputs & Assumptions'!$D$110+21)<='Inputs & Assumptions'!$C$13,INDEX('Inputs & Assumptions'!$D$70:$D$98,'Inputs & Assumptions'!$D$110+21+1),0) -> 336367.63 | Z14: =IF(('Inputs & Assumptions'!$D$110+22)<='Inputs & Assumptions'!$C$13,INDEX('Inputs & Assumptions'!$D$70:$D$98,'Inputs & Assumptions'!$D$110+22+1),0) -> 326276.61 | AA14: =IF(('Inputs & Assumptions'!$D$110+23)<='Inputs & Assumptions'!$C$13,INDEX('Inputs & Assumptions'!$D$70:$D$98,'Inputs & Assumptions'!$D$110+23+1),0) -> 316488.31 | AB14: =IF(('Inputs & Assumptions'!$D$110+24)<='Inputs & Assumptions'!$C$13,INDEX('Inputs & Assumptions'!$D$70:$D$98,'Inputs & Assumptions'!$D$110+24+1),0) -> 306993.66 | AC14: =IF(('Inputs & Assumptions'!$D$110+25)<='Inputs & Assumptions'!$C$13,INDEX('Inputs & Assumptions'!$D$70:$D$98,'Inputs & Assumptions'!$D$110+25+1),0) -> 9926128.3 | AD14: =IF(('Inputs & Assumptions'!$D$110+26)<='Inputs & Assumptions'!$C$13,INDEX('Inputs & Assumptions'!$D$70:$D$98,'Inputs & Assumptions'!$D$110+26+1),0) -> 0 | AE14: =IF(('Inputs & Assumptions'!$D$110+27)<='Inputs & Assumptions'!$C$13,INDEX('Inputs & Assumptions'!$D$70:$D$98,'Inputs & Assumptions'!$D$110+27+1),0) -> 0 | AF14: =IF(('Inputs & Assumptions'!$D$110+28)<='Inputs & Assumptions'!$C$13,INDEX('Inputs & Assumptions'!$D$70:$D$98,'Inputs & Assumptions'!$D$110+28+1),0) -> 0 | AG14: =IF(('Inputs & Assumptions'!$D$110+29)<='Inputs & Assumptions'!$C$13,INDEX('Inputs & Assumptions'!$D$70:$D$98,'Inputs & Assumptions'!$D$110+29+1),0) -> 0 | AH14: =IF(('Inputs & Assumptions'!$D$110+30)<='Inputs & Assumptions'!$C$13,INDEX('Inputs & Assumptions'!$D$70:$D$98,'Inputs & Assumptions'!$D$110+30+1),0) -> 0 | AI14: =IF(('Inputs & Assumptions'!$D$110+31)<='Inputs & Assumptions'!$C$13,INDEX('Inputs & Assumptions'!$D$70:$D$98,'Inputs & Assumptions'!$D$110+31+1),0) -> 0 | AJ14: =IF(('Inputs & Assumptions'!$D$110+32)<='Inputs & Assumptions'!$C$13,INDEX('Inputs & Assumptions'!$D$70:$D$98,'Inputs & Assumptions'!$D$110+32+1),0) -> 0 | AK14: =IF(('Inputs & Assumptions'!$D$110+33)<='Inputs & Assumptions'!$C$13,INDEX('Inputs & Assumptions'!$D$70:$D$98,'Inputs & Assumptions'!$D$110+33+1),0) -> 0 | AL14: =IF(('Inputs & Assumptions'!$D$110+34)<='Inputs & Assumptions'!$C$13,INDEX('Inputs & Assumptions'!$D$70:$D$98,'Inputs & Assumptions'!$D$110+34+1),0) -> 0 | AM14: =IF(('Inputs & Assumptions'!$D$110+35)<='Inputs & Assumptions'!$C$13,INDEX('Inputs & Assumptions'!$D$70:$D$98,'Inputs & Assumptions'!$D$110+35+1),0) -> 0 | AN14: =IF(('Inputs & Assumptions'!$D$110+36)<='Inputs & Assumptions'!$C$13,INDEX('Inputs & Assumptions'!$D$70:$D$98,'Inputs & Assumptions'!$D$110+36+1),0) -> 0
